Workbook

Sheet Start Here
B2: Start Here
B3: Welcome to Loadscope™. Here's how to find your best load from a range trip.
B5: How to label your CSVs
B6: Type the label as your session name in Garmin ShotView, your group name in BallisticX, or by renaming the CSV file after export. Loadscope reads it from any of those.
B7: Each label has 3 parts, separated by spaces: [ test tag ] [ grains of powder ] [ powder type ]
B8: Example label | D8: What each part means
B9: P1 45.5 H4350 | D9: P1 → Powder Ladder, Load #1 45.5 → 45.5 grains of powder H4350 → Powder type (Hodgdon H4350)
B10: S7 0.070 H4350 | D10: S7 → Seating Depth, Test #7 0.070 → 0.070-inch jump distance H4350 → Powder type (Hodgdon H4350)
B12: How to import your range data
B13: ① | C13: Drop your properly labeled Garmin Xero and BallisticX CSV files onto Loadscope — either onto the app icon in your Dock, or onto the drop zone in the Loadscope window.
B14: ② | C14: Click Run Import. Loadscope sorts the files into the right folders and writes the data into your workbook.
B15: ③ | C15: Your workbook opens in Excel with every row filled in. Visit the Charts tab to see your suggested winner.
B17: What's on each tab
B18: Load Log | C18: Your powder ladder. Date, powder, bullet, and cartridge auto-fill from your CSVs. You fill in your rifle setup once (rifle, scope, click size, primer, brass, CBTO, OAL) — those values flow into Seating Depth, Ballistics, and your Pocket Range Card automatically. The orange button jumps you to Charts.
B19: Seating Depth | C19: Your seating-depth test data. Same idea as Load Log, one row per jump distance.
B20: Charts | C20: Your suggested best load. Loadscope ranks every powder ladder candidate by composite score. Save the winner to your Library with one click.
B21: Ballistics | C21: Your DOPE table. Type in the elevation and wind values you dialed at the range — click counts auto-fill. Print a 4×6 Pocket Range Card from the orange button.
B22: Load Library | C22: Every confirmed load you've saved over time, one row per load.
B23: Garmin Xero & BallisticX Import | C23: Auto-populated from your CSVs. You usually won't need to edit these — they feed Load Log + Seating Depth.
B25: Starting a new load cycle (different cartridge, bullet, or powder)
B26: In Loadscope, click Workbook → Start New Cycle… and give it a name like "6.5 CM 140 ELD-M H4350." Loadscope archives your finished workbook and CSVs, then makes a fresh workbook your active one. From there, drop your new CSVs in and click Run Import.
B28: Something not working?
B29: Excel says 'Protected View' | D29: macOS marks files from email or AirDrop as untrusted. Click the yellow Enable Editing bar at the top of the workbook.
B30: A row stays blank | D30: The first word of the Garmin label or BallisticX file name must match the row's tag (P1, P2, S1, etc.).
B31: Charge or Jump value is blank | D31: The label was missing the number or had a typo. Open the Garmin Xero Import or BallisticX Import tab and fix it directly.
B32: Run Import won't go | D32: Excel is probably open. Close Excel (Cmd+Q) and click Run Import again.
B33: Click counts on Ballistics look wrong | D33: Check the Click: dropdown on the Load Log tab and pick the right one for your scope.
B34: Charts tab is empty | D34: Loadscope needs at least 2 candidate loads with BOTH chronograph AND target data to score them. Drop more CSVs and re-run import.
B35: Print Pocket Range Card button does nothing | D35: Make sure Loadscope is in /Applications and you've opened it once. The button uses a loadscope:// URL that needs the app registered.
B37: Need more help? See Loadscope — Quick Start.docx in your project folder · 🖨 Cmd+P to print this page.
B38: 📧 Email us: support@loadscope.app

Sheet Powder Charge Log
A1: Powder Charge Test — Best Charge Finder
A2: SUGGESTED CHARGE → | D2: 42.4 | F2: Avg Vel: | G2: 2780 | I2: SD: | J2: 2.5 | K2: MR: | L2: 0.18 | M2: Best in: All metrics ✓
A3: ↓ Click here to jump to the Charts sheet (Suggested Best Load) ↓
A4: RIFLE & SHOOTER
A5: Rifle: | B5: Tikka T3X CTR 6.5 CM | F5: Shooter: | G5: Demo Shooter | K5: Cartridge: | L5: 6.5 Creedmoor
A6: Barrel: | B6: 24" 1:8 twist, threaded muzzle | F6: Optic: | G6: Leupold Mark 5HD 5-25x56 | K6: Chrono: | L6: Garmin Xero C1 Pro
F7: Turret: | G7: 0.1 Mil
A8: LOAD COMPONENTS (constants for this powder ladder)
A9: Bullet: | B9: Hornady 140gr ELD-M | F9: Powder: | G9: =IFERROR(LOOKUP(2,1/(GarminSessions!$C$2:$C$200<>""),GarminSessions!$C$2:$C$200),"") -> H4350 | K9: Primer: | L9: CCI BR-2 | N9: Brass: | O9: Hornady
A10: CBTO: | B10: 2.224 | F10: OAL: | G10: 2.875 | K10: Dist: | L10: 100
A12: TEST SESSION (date / conditions)
A13: Date: | B13: 46124 | F13: Temp: | G13: 68 | K13: Notes: | L13: Sunny, light breeze. 1500 ft DA.
A15: Load # | B15: Charge (gr) | C15: Shot 1 | D15: Shot 2 | E15: Shot 3 | F15: Shot 4 | G15: Shot 5 | H15: Avg Vel | I15: ES | J15: SD | K15: Group (in) | L15: Vertical (in) | M15: Vertical SD (in) | N15: Mean Radius (in) | O15: Composite Score | P15: Winner
A16: 1 | B16: =IFERROR(LOOKUP(2,1/(GarminSessions!$A$2:$A$200="P1"),GarminSessions!$B$2:$B$200),NA()) -> 41.5 | C16: =IF(OR('Garmin Xero Import'!E6="",'Garmin Xero Import'!E6=0),"",'Garmin Xero Import'!E6) -> 2710 | D16: =IF(OR('Garmin Xero Import'!F6="",'Garmin Xero Import'!F6=0),"",'Garmin Xero Import'!F6) -> 2718 | E16: =IF(OR('Garmin Xero Import'!G6="",'Garmin Xero Import'!G6=0),"",'Garmin Xero Import'!G6) -> 2705 | F16: =IF(OR('Garmin Xero Import'!H6="",'Garmin Xero Import'!H6=0),"",'Garmin Xero Import'!H6) -> 2720 | G16: =IF(OR('Garmin Xero Import'!I6="",'Garmin Xero Import'!I6=0),"",'Garmin Xero Import'!I6) -> 2715 | H16: =IF(OR('Garmin Xero Import'!O6="",'Garmin Xero Import'!O6=0),NA(),'Garmin Xero Import'!O6) -> 2715 | I16: =IF(OR('Garmin Xero Import'!Q6="",'Garmin Xero Import'!Q6=0),"",'Garmin Xero Import'!Q6) -> 19 | J16: =IF(OR('Garmin Xero Import'!P6="",'Garmin Xero Import'!P6=0),NA(),'Garmin Xero Import'!P6) -> 6.7 | K16: =IF(OR('BallisticX Import'!D6="",'BallisticX Import'!D6=0),NA(),'BallisticX Import'!D6) -> 0.62 | L16: =IF(OR('BallisticX Import'!F6="",'BallisticX Import'!F6=0),"",'BallisticX Import'!F6) -> 0.55 | M16: =IF(OR('BallisticX Import'!J6="",'BallisticX Import'!J6=0),"",'BallisticX Import'!J6) -> 0.2 | N16: =IF(OR('BallisticX Import'!G6="",'BallisticX Import'!G6=0),"",'BallisticX Import'!G6) -> 0.31 | O16: 0.606
A17: 2 | B17: =IFERROR(LOOKUP(2,1/(GarminSessions!$A$2:$A$200="P2"),GarminSessions!$B$2:$B$200),NA()) -> 41.8 | C17: =IF(OR('Garmin Xero Import'!E7="",'Garmin Xero Import'!E7=0),"",'Garmin Xero Import'!E7) -> 2732 | D17: =IF(OR('Garmin Xero Import'!F7="",'Garmin Xero Import'!F7=0),"",'Garmin Xero Import'!F7) -> 2748 | E17: =IF(OR('Garmin Xero Import'!G7="",'Garmin Xero Import'!G7=0),"",'Garmin Xero Import'!G7) -> 2725 | F17: =IF(OR('Garmin Xero Import'!H7="",'Garmin Xero Import'!H7=0),"",'Garmin Xero Import'!H7) -> 2740 | G17: =IF(OR('Garmin Xero Import'!I7="",'Garmin Xero Import'!I7=0),"",'Garmin Xero Import'!I7) -> 2738 | H17: =IF(OR('Garmin Xero Import'!O7="",'Garmin Xero Import'!O7=0),NA(),'Garmin Xero Import'!O7) -> 2737 | I17: =IF(OR('Garmin Xero Import'!Q7="",'Garmin Xero Import'!Q7=0),"",'Garmin Xero Import'!Q7) -> 23 | J17: =IF(OR('Garmin Xero Import'!P7="",'Garmin Xero Import'!P7=0),NA(),'Garmin Xero Import'!P7) -> 7.8 | K17: =IF(OR('BallisticX Import'!D7="",'BallisticX Import'!D7=0),NA(),'BallisticX Import'!D7) -> 0.81 | L17: =IF(OR('BallisticX Import'!F7="",'BallisticX Import'!F7=0),"",'BallisticX Import'!F7) -> 0.72 | M17: =IF(OR('BallisticX Import'!J7="",'BallisticX Import'!J7=0),"",'BallisticX Import'!J7) -> 0.26 | N17: =IF(OR('BallisticX Import'!G7="",'BallisticX Import'!G7=0),"",'BallisticX Import'!G7) -> 0.42 | O17: 1
A18: 3 | B18: =IFERROR(LOOKUP(2,1/(GarminSessions!$A$2:$A$200="P3"),GarminSessions!$B$2:$B$200),NA()) -> 42.1 | C18: =IF(OR('Garmin Xero Import'!E8="",'Garmin Xero Import'!E8=0),"",'Garmin Xero Import'!E8) -> 2755 | D18: =IF(OR('Garmin Xero Import'!F8="",'Garmin Xero Import'!F8=0),"",'Garmin Xero Import'!F8) -> 2762 | E18: =IF(OR('Garmin Xero Import'!G8="",'Garmin Xero Import'!G8=0),"",'Garmin Xero Import'!G8) -> 2750 | F18: =IF(OR('Garmin Xero Import'!H8="",'Garmin Xero Import'!H8=0),"",'Garmin Xero Import'!H8) -> 2768 | G18: =IF(OR('Garmin Xero Import'!I8="",'Garmin Xero Import'!I8=0),"",'Garmin Xero Import'!I8) -> 2760 | H18: =IF(OR('Garmin Xero Import'!O8="",'Garmin Xero Import'!O8=0),NA(),'Garmin Xero Import'!O8) -> 2760 | I18: =IF(OR('Garmin Xero Import'!Q8="",'Garmin Xero Import'!Q8=0),"",'Garmin Xero Import'!Q8) -> 20 | J18: =IF(OR('Garmin Xero Import'!P8="",'Garmin Xero Import'!P8=0),NA(),'Garmin Xero Import'!P8) -> 6.4 | K18: =IF(OR('BallisticX Import'!D8="",'BallisticX Import'!D8=0),NA(),'BallisticX Import'!D8) -> 0.45 | L18: =IF(OR('BallisticX Import'!F8="",'BallisticX Import'!F8=0),"",'BallisticX Import'!F8) -> 0.4 | M18: =IF(OR('BallisticX Import'!J8="",'BallisticX Import'!J8=0),"",'BallisticX Import'!J8) -> 0.14 | N18: =IF(OR('BallisticX Import'!G8="",'BallisticX Import'!G8=0),"",'BallisticX Import'!G8) -> 0.22 | O18: 0.272 | P18: 🥈 2nd
A19: 4 | B19: =IFERROR(LOOKUP(2,1/(GarminSessions!$A$2:$A$200="P4"),GarminSessions!$B$2:$B$200),NA()) -> 42.4 | C19: =IF(OR('Garmin Xero Import'!E9="",'Garmin Xero Import'!E9=0),"",'Garmin Xero Import'!E9) -> 2778 | D19: =IF(OR('Garmin Xero Import'!F9="",'Garmin Xero Import'!F9=0),"",'Garmin Xero Import'!F9) -> 2782 | E19: =IF(OR('Garmin Xero Import'!G9="",'Garmin Xero Import'!G9=0),"",'Garmin Xero Import'!G9) -> 2776 | F19: =IF(OR('Garmin Xero Import'!H9="",'Garmin Xero Import'!H9=0),"",'Garmin Xero Import'!H9) -> 2784 | G19: =IF(OR('Garmin Xero Import'!I9="",'Garmin Xero Import'!I9=0),"",'Garmin Xero Import'!I9) -> 2780 | H19: =IF(OR('Garmin Xero Import'!O9="",'Garmin Xero Import'!O9=0),NA(),'Garmin Xero Import'!O9) -> 2780 | I19: =IF(OR('Garmin Xero Import'!Q9="",'Garmin Xero Import'!Q9=0),"",'Garmin Xero Import'!Q9) -> 8 | J19: =IF(OR('Garmin Xero Import'!P9="",'Garmin Xero Import'!P9=0),NA(),'Garmin Xero Import'!P9) -> 2.5 | K19: =IF(OR('BallisticX Import'!D9="",'BallisticX Import'!D9=0),NA(),'BallisticX Import'!D9) -> 0.38 | L19: =IF(OR('BallisticX Import'!F9="",'BallisticX Import'!F9=0),"",'BallisticX Import'!F9) -> 0.32 | M19: =IF(OR('BallisticX Import'!J9="",'BallisticX Import'!J9=0),"",'BallisticX Import'!J9) -> 0.12 | N19: =IF(OR('BallisticX Import'!G9="",'BallisticX Import'!G9=0),"",'BallisticX Import'!G9) -> 0.18 | O19: 0.001 | P19: 🥇 WINNER
A20: 5 | B20: =IFERROR(LOOKUP(2,1/(GarminSessions!$A$2:$A$200="P5"),GarminSessions!$B$2:$B$200),NA()) -> 42.7 | C20: =IF(OR('Garmin Xero Import'!E10="",'Garmin Xero Import'!E10=0),"",'Garmin Xero Import'!E10) -> 2798 | D20: =IF(OR('Garmin Xero Import'!F10="",'Garmin Xero Import'!F10=0),"",'Garmin Xero Import'!F10) -> 2805 | E20: =IF(OR('Garmin Xero Import'!G10="",'Garmin Xero Import'!G10=0),"",'Garmin Xero Import'!G10) -> 2795 | F20: =IF(OR('Garmin Xero Import'!H10="",'Garmin Xero Import'!H10=0),"",'Garmin Xero Import'!H10) -> 2812 | G20: =IF(OR('Garmin Xero Import'!I10="",'Garmin Xero Import'!I10=0),"",'Garmin Xero Import'!I10) -> 2800 | H20: =IF(OR('Garmin Xero Import'!O10="",'Garmin Xero Import'!O10=0),NA(),'Garmin Xero Import'!O10) -> 2803 | I20: =IF(OR('Garmin Xero Import'!Q10="",'Garmin Xero Import'!Q10=0),"",'Garmin Xero Import'!Q10) -> 17 | J20: =IF(OR('Garmin Xero Import'!P10="",'Garmin Xero Import'!P10=0),NA(),'Garmin Xero Import'!P10) -> 5.6 | K20: =IF(OR('BallisticX Import'!D10="",'BallisticX Import'!D10=0),NA(),'BallisticX Import'!D10) -> 0.58 | L20: =IF(OR('BallisticX Import'!F10="",'BallisticX Import'!F10=0),"",'BallisticX Import'!F10) -> 0.52 | M20: =IF(OR('BallisticX Import'!J10="",'BallisticX Import'!J10=0),"",'BallisticX Import'!J10) -> 0.18 | N20: =IF(OR('BallisticX Import'!G10="",'BallisticX Import'!G10=0),"",'BallisticX Import'!G10) -> 0.29 | O20: 0.477 | P20: 🥉 3rd
A21: 6 | B21: =IFERROR(LOOKUP(2,1/(GarminSessions!$A$2:$A$200="P6"),GarminSessions!$B$2:$B$200),NA()) -> #N/A | C21: =IF(OR('Garmin Xero Import'!E11="",'Garmin Xero Import'!E11=0),"",'Garmin Xero Import'!E11) | D21: =IF(OR('Garmin Xero Import'!F11="",'Garmin Xero Import'!F11=0),"",'Garmin Xero Import'!F11) | E21: =IF(OR('Garmin Xero Import'!G11="",'Garmin Xero Import'!G11=0),"",'Garmin Xero Import'!G11) | F21: =IF(OR('Garmin Xero Import'!H11="",'Garmin Xero Import'!H11=0),"",'Garmin Xero Import'!H11) | G21: =IF(OR('Garmin Xero Import'!I11="",'Garmin Xero Import'!I11=0),"",'Garmin Xero Import'!I11) | H21: =IF(OR('Garmin Xero Import'!O11="",'Garmin Xero Import'!O11=0),NA(),'Garmin Xero Import'!O11) -> #N/A | I21: =IF(OR('Garmin Xero Import'!Q11="",'Garmin Xero Import'!Q11=0),"",'Garmin Xero Import'!Q11) | J21: =IF(OR('Garmin Xero Import'!P11="",'Garmin Xero Import'!P11=0),NA(),'Garmin Xero Import'!P11) -> #N/A | K21: =IF(OR('BallisticX Import'!D11="",'BallisticX Import'!D11=0),NA(),'BallisticX Import'!D11) -> #N/A | L21: =IF(OR('BallisticX Import'!F11="",'BallisticX Import'!F11=0),"",'BallisticX Import'!F11) | M21: =IF(OR('BallisticX Import'!J11="",'BallisticX Import'!J11=0),"",'BallisticX Import'!J11) | N21: =IF(OR('BallisticX Import'!G11="",'BallisticX Import'!G11=0),"",'BallisticX Import'!G11) | O21: =NA() -> #N/A
A22: 7 | B22: =IFERROR(LOOKUP(2,1/(GarminSessions!$A$2:$A$200="P7"),GarminSessions!$B$2:$B$200),NA()) -> #N/A | C22: =IF(OR('Garmin Xero Import'!E12="",'Garmin Xero Import'!E12=0),"",'Garmin Xero Import'!E12) | D22: =IF(OR('Garmin Xero Import'!F12="",'Garmin Xero Import'!F12=0),"",'Garmin Xero Import'!F12) | E22: =IF(OR('Garmin Xero Import'!G12="",'Garmin Xero Import'!G12=0),"",'Garmin Xero Import'!G12) | F22: =IF(OR('Garmin Xero Import'!H12="",'Garmin Xero Import'!H12=0),"",'Garmin Xero Import'!H12) | G22: =IF(OR('Garmin Xero Import'!I12="",'Garmin Xero Import'!I12=0),"",'Garmin Xero Import'!I12) | H22: =IF(OR('Garmin Xero Import'!O12="",'Garmin Xero Import'!O12=0),NA(),'Garmin Xero Import'!O12) -> #N/A | I22: =IF(OR('Garmin Xero Import'!Q12="",'Garmin Xero Import'!Q12=0),"",'Garmin Xero Import'!Q12) | J22: =IF(OR('Garmin Xero Import'!P12="",'Garmin Xero Import'!P12=0),NA(),'Garmin Xero Import'!P12) -> #N/A | K22: =IF(OR('BallisticX Import'!D12="",'BallisticX Import'!D12=0),NA(),'BallisticX Import'!D12) -> #N/A | L22: =IF(OR('BallisticX Import'!F12="",'BallisticX Import'!F12=0),"",'BallisticX Import'!F12) | M22: =IF(OR('BallisticX Import'!J12="",'BallisticX Import'!J12=0),"",'BallisticX Import'!J12) | N22: =IF(OR('BallisticX Import'!G12="",'BallisticX Import'!G12=0),"",'BallisticX Import'!G12) | O22: =NA() -> #N/A
A23: 8 | B23: =IFERROR(LOOKUP(2,1/(GarminSessions!$A$2:$A$200="P8"),GarminSessions!$B$2:$B$200),NA()) -> #N/A | C23: =IF(OR('Garmin Xero Import'!E13="",'Garmin Xero Import'!E13=0),"",'Garmin Xero Import'!E13) | D23: =IF(OR('Garmin Xero Import'!F13="",'Garmin Xero Import'!F13=0),"",'Garmin Xero Import'!F13) | E23: =IF(OR('Garmin Xero Import'!G13="",'Garmin Xero Import'!G13=0),"",'Garmin Xero Import'!G13) | F23: =IF(OR('Garmin Xero Import'!H13="",'Garmin Xero Import'!H13=0),"",'Garmin Xero Import'!H13) | G23: =IF(OR('Garmin Xero Import'!I13="",'Garmin Xero Import'!I13=0),"",'Garmin Xero Import'!I13) | H23: =IF(OR('Garmin Xero Import'!O13="",'Garmin Xero Import'!O13=0),NA(),'Garmin Xero Import'!O13) -> #N/A | I23: =IF(OR('Garmin Xero Import'!Q13="",'Garmin Xero Import'!Q13=0),"",'Garmin Xero Import'!Q13) | J23: =IF(OR('Garmin Xero Import'!P13="",'Garmin Xero Import'!P13=0),NA(),'Garmin Xero Import'!P13) -> #N/A | K23: =IF(OR('BallisticX Import'!D13="",'BallisticX Import'!D13=0),NA(),'BallisticX Import'!D13) -> #N/A | L23: =IF(OR('BallisticX Import'!F13="",'BallisticX Import'!F13=0),"",'BallisticX Import'!F13) | M23: =IF(OR('BallisticX Import'!J13="",'BallisticX Import'!J13=0),"",'BallisticX Import'!J13) | N23: =IF(OR('BallisticX Import'!G13="",'BallisticX Import'!G13=0),"",'BallisticX Import'!G13) | O23: =NA() -> #N/A
A24: 9 | B24: =IFERROR(LOOKUP(2,1/(GarminSessions!$A$2:$A$200="P9"),GarminSessions!$B$2:$B$200),NA()) -> #N/A | C24: =IF(OR('Garmin Xero Import'!E14="",'Garmin Xero Import'!E14=0),"",'Garmin Xero Import'!E14) | D24: =IF(OR('Garmin Xero Import'!F14="",'Garmin Xero Import'!F14=0),"",'Garmin Xero Import'!F14) | E24: =IF(OR('Garmin Xero Import'!G14="",'Garmin Xero Import'!G14=0),"",'Garmin Xero Import'!G14) | F24: =IF(OR('Garmin Xero Import'!H14="",'Garmin Xero Import'!H14=0),"",'Garmin Xero Import'!H14) | G24: =IF(OR('Garmin Xero Import'!I14="",'Garmin Xero Import'!I14=0),"",'Garmin Xero Import'!I14) | H24: =IF(OR('Garmin Xero Import'!O14="",'Garmin Xero Import'!O14=0),NA(),'Garmin Xero Import'!O14) -> #N/A | I24: =IF(OR('Garmin Xero Import'!Q14="",'Garmin Xero Import'!Q14=0),"",'Garmin Xero Import'!Q14) | J24: =IF(OR('Garmin Xero Import'!P14="",'Garmin Xero Import'!P14=0),NA(),'Garmin Xero Import'!P14) -> #N/A | K24: =IF(OR('BallisticX Import'!D14="",'BallisticX Import'!D14=0),NA(),'BallisticX Import'!D14) -> #N/A | L24: =IF(OR('BallisticX Import'!F14="",'BallisticX Import'!F14=0),"",'BallisticX Import'!F14) | M24: =IF(OR('BallisticX Import'!J14="",'BallisticX Import'!J14=0),"",'BallisticX Import'!J14) | N24: =IF(OR('BallisticX Import'!G14="",'BallisticX Import'!G14=0),"",'BallisticX Import'!G14) | O24: =NA() -> #N/A
A25: 10 | B25: =IFERROR(LOOKUP(2,1/(GarminSessions!$A$2:$A$200="P10"),GarminSessions!$B$2:$B$200),NA()) -> #N/A | C25: =IF(OR('Garmin Xero Import'!E15="",'Garmin Xero Import'!E15=0),"",'Garmin Xero Import'!E15) | D25: =IF(OR('Garmin Xero Import'!F15="",'Garmin Xero Import'!F15=0),"",'Garmin Xero Import'!F15) | E25: =IF(OR('Garmin Xero Import'!G15="",'Garmin Xero Import'!G15=0),"",'Garmin Xero Import'!G15) | F25: =IF(OR('Garmin Xero Import'!H15="",'Garmin Xero Import'!H15=0),"",'Garmin Xero Import'!H15) | G25: =IF(OR('Garmin Xero Import'!I15="",'Garmin Xero Import'!I15=0),"",'Garmin Xero Import'!I15) | H25: =IF(OR('Garmin Xero Import'!O15="",'Garmin Xero Import'!O15=0),NA(),'Garmin Xero Import'!O15) -> #N/A | I25: =IF(OR('Garmin Xero Import'!Q15="",'Garmin Xero Import'!Q15=0),"",'Garmin Xero Import'!Q15) | J25: =IF(OR('Garmin Xero Import'!P15="",'Garmin Xero Import'!P15=0),NA(),'Garmin Xero Import'!P15) -> #N/A | K25: =IF(OR('BallisticX Import'!D15="",'BallisticX Import'!D15=0),NA(),'BallisticX Import'!D15) -> #N/A | L25: =IF(OR('BallisticX Import'!F15="",'BallisticX Import'!F15=0),"",'BallisticX Import'!F15) | M25: =IF(OR('BallisticX Import'!J15="",'BallisticX Import'!J15=0),"",'BallisticX Import'!J15) | N25: =IF(OR('BallisticX Import'!G15="",'BallisticX Import'!G15=0),"",'BallisticX Import'!G15) | O25: =NA() -> #N/A
A27: COMPARISON CHARTS

Sheet Charts
A1: SUGGESTED BEST LOAD — Velocity + SD + Group Cross-Check
A3: SUGGESTED CHARGE: | B3: 42.4 | D3: Composite: | E3: 0.001 | F3: SD: | G3: 2.5
D4: =IF($B$100="window","Vel Spread:","") | E4: =IF($B$100="window",IFERROR(INDEX(D18:D25,MATCH(MIN(L18:L25),L18:L25,0)),""),"") | F4: Group: | G4: 0.18
D5: Avg Vel: | E5: 2780 | F5: Best in: | G5: All metrics ✓
A6: → Save Suggested Load to Library ←
A7: Method: each middle charge of a 3-load window is scored on velocity spread, SD, mean radius (MOA), and Vertical SD (MOA) — each normalized 0-1, 0=best. Combined using the weights below (sum must = 1.0). Lowest composite score wins. Vertical SD falls back to Height, then MR, if the BallisticX export is missing the statistic.
A8: NOTE: Loadscope ranks the charges you entered by your weighted scoring criteria. It does not certify safe charges, recommend loads, or assess pressure. Always cross-reference every charge weight against current published load data from your powder, bullet, and cartridge manufacturers before shooting.
A10: WEIGHTS — adjust the blue cells to tune what matters most to you (must sum to 1.0).
A11: Velocity | B11: 0.3 | C11: SD | D11: 0.2 | E11: MR | F11: 0.2 | G11: Vertical SD | H11: 0.3 | I11: Sum: | J11: =SUM(B11,D11,F11,H11) -> 1
A12: → Reset weights to Loadscope defaults ←
A13: Powder ladder
A14: → Print This Workbook ←
A17: Charge | D17: Avg Vel (fps) | E17: SD (fps) | F17: Mean Radius (MOA) | G17: Vertical SD (MOA) | H17: Norm Vel | I17: Norm SD | J17: Norm MR | K17: Norm Vertical SD | L17: Composite Score | M17: Chart: Vel Spread | N17: Chart: SD | O17: Chart: MR | P17: Chart: Vert | Q17: Chart: Composite | R17: Best in (per row) | T17: Sort Charge | U17: Sort Vel
A18: =IFERROR(IF($B$100="window",'Powder Charge Log'!B17,IF('Powder Charge Log'!B16="","",'Powder Charge Log'!B16)),"") -> 41.5 | D18: 2715 | E18: 6.7 | F18: 0.31 | G18: 0.2 | H18: 0.558 | I18: 0.792 | J18: 0.542 | K18: 0.571 | L18: 0.606 | M18: =IF(D18="",NA(),H18) -> 0.558 | N18: =IF(D18="",NA(),I18) -> 0.792 | O18: =IF(D18="",NA(),J18) -> 0.542 | P18: =IF(D18="",NA(),K18) -> 0.571 | Q18: =IF(D18="",NA(),L18) -> 0.606 | R18: =IFERROR(IF(D18=_xludf.AGGREGATE(5,6,$D$18:$D$25),"Vel ✓ ","")&IF(E18=_xludf.AGGREGATE(5,6,$E$18:$E$25),"SD ✓ ","")&IF(F18=_xludf.AGGREGATE(5,6,$F$18:$F$25),"MR ✓ ","")&IF(G18=_xludf.AGGREGATE(5,6,$G$18:$G$25),"Vert ✓ ",""),"") | T18: 41.5 | U18: 2715
A19: =IFERROR(IF($B$100="window",'Powder Charge Log'!B18,IF('Powder Charge Log'!B17="","",'Powder Charge Log'!B17)),"") -> 41.8 | D19: 2737 | E19: 7.8 | F19: 0.42 | G19: 0.26 | H19: 1 | I19: 1 | J19: 1 | K19: 1 | L19: 1 | M19: =IF(D19="",NA(),H19) -> 1 | N19: =IF(D19="",NA(),I19) -> 1 | O19: =IF(D19="",NA(),J19) -> 1 | P19: =IF(D19="",NA(),K19) -> 1 | Q19: =IF(D19="",NA(),L19) -> 1 | R19: =IFERROR(IF(D19=_xludf.AGGREGATE(5,6,$D$18:$D$25),"Vel ✓ ","")&IF(E19=_xludf.AGGREGATE(5,6,$E$18:$E$25),"SD ✓ ","")&IF(F19=_xludf.AGGREGATE(5,6,$F$18:$F$25),"MR ✓ ","")&IF(G19=_xludf.AGGREGATE(5,6,$G$18:$G$25),"Vert ✓ ",""),"") | T19: 41.8 | U19: 2737
A20: =IFERROR(IF($B$100="window",'Powder Charge Log'!B19,IF('Powder Charge Log'!B18="","",'Powder Charge Log'!B18)),"") -> 42.1 | D20: 2760 | E20: 6.4 | F20: 0.22 | G20: 0.14 | H20: 0.163 | I20: 0.736 | J20: 0.167 | K20: 0.143 | L20: 0.272 | M20: =IF(D20="",NA(),H20) -> 0.163 | N20: =IF(D20="",NA(),I20) -> 0.736 | O20: =IF(D20="",NA(),J20) -> 0.167 | P20: =IF(D20="",NA(),K20) -> 0.143 | Q20: =IF(D20="",NA(),L20) -> 0.272 | R20: =IFERROR(IF(D20=_xludf.AGGREGATE(5,6,$D$18:$D$25),"Vel ✓ ","")&IF(E20=_xludf.AGGREGATE(5,6,$E$18:$E$25),"SD ✓ ","")&IF(F20=_xludf.AGGREGATE(5,6,$F$18:$F$25),"MR ✓ ","")&IF(G20=_xludf.AGGREGATE(5,6,$G$18:$G$25),"Vert ✓ ",""),"") | T20: 42.1 | U20: 2760
A21: =IFERROR(IF($B$100="window",'Powder Charge Log'!B20,IF('Powder Charge Log'!B19="","",'Powder Charge Log'!B19)),"") -> 42.4 | D21: 2780 | E21: 2.5 | F21: 0.18 | G21: 0.12 | H21: 0.001 | I21: 0.001 | J21: 0.001 | K21: 0.001 | L21: 0.001 | M21: =IF(D21="",NA(),H21) -> 0.001 | N21: =IF(D21="",NA(),I21) -> 0.001 | O21: =IF(D21="",NA(),J21) -> 0.001 | P21: =IF(D21="",NA(),K21) -> 0.001 | Q21: =IF(D21="",NA(),L21) -> 0.001 | R21: All metrics ✓ | T21: 42.4 | U21: 2780
A22: =IFERROR(IF($B$100="window",'Powder Charge Log'!B21,IF('Powder Charge Log'!B20="","",'Powder Charge Log'!B20)),"") -> 42.7 | D22: 2803 | E22: 5.6 | F22: 0.29 | G22: 0.18 | H22: 0.465 | I22: 0.585 | J22: 0.458 | K22: 0.429 | L22: 0.477 | M22: =IF(D22="",NA(),H22) -> 0.465 | N22: =IF(D22="",NA(),I22) -> 0.585 | O22: =IF(D22="",NA(),J22) -> 0.458 | P22: =IF(D22="",NA(),K22) -> 0.429 | Q22: =IF(D22="",NA(),L22) -> 0.477 | R22: =IFERROR(IF(D22=_xludf.AGGREGATE(5,6,$D$18:$D$25),"Vel ✓ ","")&IF(E22=_xludf.AGGREGATE(5,6,$E$18:$E$25),"SD ✓ ","")&IF(F22=_xludf.AGGREGATE(5,6,$F$18:$F$25),"MR ✓ ","")&IF(G22=_xludf.AGGREGATE(5,6,$G$18:$G$25),"Vert ✓ ",""),"") | T22: 42.7 | U22: 2803
A23: =IFERROR(IF($B$100="window",'Powder Charge Log'!B22,IF('Powder Charge Log'!B21="","",'Powder Charge Log'!B21)),"") | B23: =IFERROR(IF($B$100="window",'Powder Charge Log'!B21,""),"") | C23: =IFERROR(IF($B$100="window",'Powder Charge Log'!B23,""),"") | D23: =IF($B$100="window",IF(OR(A23="",B23="",C23=""),"",MAX('Powder Charge Log'!H21:H23)-MIN('Powder Charge Log'!H21:H23)),IF('Powder Charge Log'!H21="","",'Powder Charge Log'!H21)) -> #N/A | E23: =IF($B$100="window",IF(OR(A23="",B23="",C23=""),"",'Powder Charge Log'!J22),IF('Powder Charge Log'!J21="","",'Powder Charge Log'!J21)) -> #N/A | F23: =IF($B$100="window",IF(OR(A23="",B23="",C23=""),"",IFERROR(IF('Powder Charge Log'!N22="",'Powder Charge Log'!K22,'Powder Charge Log'!N22)/('Powder Charge Log'!$L$10/100)/1.047,"")),IFERROR(IF('Powder Charge Log'!N21="",'Powder Charge Log'!K21,'Powder Charge Log'!N21)/('Powder Charge Log'!$L$10/100)/1.047,"")) | G23: =IF($B$100="window",IF(OR(A23="",B23="",C23=""),"",IF('Powder Charge Log'!M22="",IF('Powder Charge Log'!L22="",F23,'Powder Charge Log'!L22/('Powder Charge Log'!$L$10/100)/1.047),'Powder Charge Log'!M22/('Powder Charge Log'!$L$10/100)/1.047)),IF('Powder Charge Log'!M21="",IF('Powder Charge Log'!L21="",F23,'Powder Charge Log'!L21/('Powder Charge Log'!$L$10/100)/1.047),'Powder Charge Log'!M21/('Powder Charge Log'!$L$10/100)/1.047)) | H23: =IF(D23="","",IFERROR((D23-_xludf.AGGREGATE(5,6,$D$18:$D$25))/(_xludf.AGGREGATE(4,6,$D$18:$D$25)-_xludf.AGGREGATE(5,6,$D$18:$D$25)),0)) -> #N/A | I23: =IF(E23="","",IFERROR((E23-_xludf.AGGREGATE(5,6,$E$18:$E$25))/(_xludf.AGGREGATE(4,6,$E$18:$E$25)-_xludf.AGGREGATE(5,6,$E$18:$E$25)),0)) -> #N/A | J23: =IF(F23="","",IFERROR((F23-_xludf.AGGREGATE(5,6,$F$18:$F$25))/(_xludf.AGGREGATE(4,6,$F$18:$F$25)-_xludf.AGGREGATE(5,6,$F$18:$F$25)),0)) | K23: =IF(G23="","",IFERROR((G23-_xludf.AGGREGATE(5,6,$G$18:$G$25))/(_xludf.AGGREGATE(4,6,$G$18:$G$25)-_xludf.AGGREGATE(5,6,$G$18:$G$25)),0)) | L23: =IF(A23="","",H23*$B$11+I23*$D$11+J23*$F$11+K23*$H$11) | M23: =IF(D23="",NA(),H23) -> #N/A | N23: =IF(D23="",NA(),I23) -> #N/A | O23: =IF(D23="",NA(),J23) -> #N/A | P23: =IF(D23="",NA(),K23) -> #N/A | Q23: =IF(D23="",NA(),L23) -> #N/A | R23: =IFERROR(IF(D23=_xludf.AGGREGATE(5,6,$D$18:$D$25),"Vel ✓ ","")&IF(E23=_xludf.AGGREGATE(5,6,$E$18:$E$25),"SD ✓ ","")&IF(F23=_xludf.AGGREGATE(5,6,$F$18:$F$25),"MR ✓ ","")&IF(G23=_xludf.AGGREGATE(5,6,$G$18:$G$25),"Vert ✓ ",""),"") | T23: =NA() -> #N/A | U23: =NA() -> #N/A
A24: =IFERROR(IF($B$100="window",'Powder Charge Log'!B23,IF('Powder Charge Log'!B22="","",'Powder Charge Log'!B22)),"") | B24: =IFERROR(IF($B$100="window",'Powder Charge Log'!B22,""),"") | C24: =IFERROR(IF($B$100="window",'Powder Charge Log'!B24,""),"") | D24: =IF($B$100="window",IF(OR(A24="",B24="",C24=""),"",MAX('Powder Charge Log'!H22:H24)-MIN('Powder Charge Log'!H22:H24)),IF('Powder Charge Log'!H22="","",'Powder Charge Log'!H22)) -> #N/A | E24: =IF($B$100="window",IF(OR(A24="",B24="",C24=""),"",'Powder Charge Log'!J23),IF('Powder Charge Log'!J22="","",'Powder Charge Log'!J22)) -> #N/A | F24: =IF($B$100="window",IF(OR(A24="",B24="",C24=""),"",IFERROR(IF('Powder Charge Log'!N23="",'Powder Charge Log'!K23,'Powder Charge Log'!N23)/('Powder Charge Log'!$L$10/100)/1.047,"")),IFERROR(IF('Powder Charge Log'!N22="",'Powder Charge Log'!K22,'Powder Charge Log'!N22)/('Powder Charge Log'!$L$10/100)/1.047,"")) | G24: =IF($B$100="window",IF(OR(A24="",B24="",C24=""),"",IF('Powder Charge Log'!M23="",IF('Powder Charge Log'!L23="",F24,'Powder Charge Log'!L23/('Powder Charge Log'!$L$10/100)/1.047),'Powder Charge Log'!M23/('Powder Charge Log'!$L$10/100)/1.047)),IF('Powder Charge Log'!M22="",IF('Powder Charge Log'!L22="",F24,'Powder Charge Log'!L22/('Powder Charge Log'!$L$10/100)/1.047),'Powder Charge Log'!M22/('Powder Charge Log'!$L$10/100)/1.047)) | H24: =IF(D24="","",IFERROR((D24-_xludf.AGGREGATE(5,6,$D$18:$D$25))/(_xludf.AGGREGATE(4,6,$D$18:$D$25)-_xludf.AGGREGATE(5,6,$D$18:$D$25)),0)) -> #N/A | I24: =IF(E24="","",IFERROR((E24-_xludf.AGGREGATE(5,6,$E$18:$E$25))/(_xludf.AGGREGATE(4,6,$E$18:$E$25)-_xludf.AGGREGATE(5,6,$E$18:$E$25)),0)) -> #N/A | J24: =IF(F24="","",IFERROR((F24-_xludf.AGGREGATE(5,6,$F$18:$F$25))/(_xludf.AGGREGATE(4,6,$F$18:$F$25)-_xludf.AGGREGATE(5,6,$F$18:$F$25)),0)) | K24: =IF(G24="","",IFERROR((G24-_xludf.AGGREGATE(5,6,$G$18:$G$25))/(_xludf.AGGREGATE(4,6,$G$18:$G$25)-_xludf.AGGREGATE(5,6,$G$18:$G$25)),0)) | L24: =IF(A24="","",H24*$B$11+I24*$D$11+J24*$F$11+K24*$H$11) | M24: =IF(D24="",NA(),H24) -> #N/A | N24: =IF(D24="",NA(),I24) -> #N/A | O24: =IF(D24="",NA(),J24) -> #N/A | P24: =IF(D24="",NA(),K24) -> #N/A | Q24: =IF(D24="",NA(),L24) -> #N/A | R24: =IFERROR(IF(D24=_xludf.AGGREGATE(5,6,$D$18:$D$25),"Vel ✓ ","")&IF(E24=_xludf.AGGREGATE(5,6,$E$18:$E$25),"SD ✓ ","")&IF(F24=_xludf.AGGREGATE(5,6,$F$18:$F$25),"MR ✓ ","")&IF(G24=_xludf.AGGREGATE(5,6,$G$18:$G$25),"Vert ✓ ",""),"") | T24: =NA() -> #N/A | U24: =NA() -> #N/A
A25: =IFERROR(IF($B$100="window",'Powder Charge Log'!B24,IF('Powder Charge Log'!B23="","",'Powder Charge Log'!B23)),"") | B25: =IFERROR(IF($B$100="window",'Powder Charge Log'!B23,""),"") | C25: =IFERROR(IF($B$100="window",'Powder Charge Log'!B25,""),"") | D25: =IF($B$100="window",IF(OR(A25="",B25="",C25=""),"",MAX('Powder Charge Log'!H23:H25)-MIN('Powder Charge Log'!H23:H25)),IF('Powder Charge Log'!H23="","",'Powder Charge Log'!H23)) -> #N/A | E25: =IF($B$100="window",IF(OR(A25="",B25="",C25=""),"",'Powder Charge Log'!J24),IF('Powder Charge Log'!J23="","",'Powder Charge Log'!J23)) -> #N/A | F25: =IF($B$100="window",IF(OR(A25="",B25="",C25=""),"",IFERROR(IF('Powder Charge Log'!N24="",'Powder Charge Log'!K24,'Powder Charge Log'!N24)/('Powder Charge Log'!$L$10/100)/1.047,"")),IFERROR(IF('Powder Charge Log'!N23="",'Powder Charge Log'!K23,'Powder Charge Log'!N23)/('Powder Charge Log'!$L$10/100)/1.047,"")) | G25: =IF($B$100="window",IF(OR(A25="",B25="",C25=""),"",IF('Powder Charge Log'!M24="",IF('Powder Charge Log'!L24="",F25,'Powder Charge Log'!L24/('Powder Charge Log'!$L$10/100)/1.047),'Powder Charge Log'!M24/('Powder Charge Log'!$L$10/100)/1.047)),IF('Powder Charge Log'!M23="",IF('Powder Charge Log'!L23="",F25,'Powder Charge Log'!L23/('Powder Charge Log'!$L$10/100)/1.047),'Powder Charge Log'!M23/('Powder Charge Log'!$L$10/100)/1.047)) | H25: =IF(D25="","",IFERROR((D25-_xludf.AGGREGATE(5,6,$D$18:$D$25))/(_xludf.AGGREGATE(4,6,$D$18:$D$25)-_xludf.AGGREGATE(5,6,$D$18:$D$25)),0)) -> #N/A | I25: =IF(E25="","",IFERROR((E25-_xludf.AGGREGATE(5,6,$E$18:$E$25))/(_xludf.AGGREGATE(4,6,$E$18:$E$25)-_xludf.AGGREGATE(5,6,$E$18:$E$25)),0)) -> #N/A | J25: =IF(F25="","",IFERROR((F25-_xludf.AGGREGATE(5,6,$F$18:$F$25))/(_xludf.AGGREGATE(4,6,$F$18:$F$25)-_xludf.AGGREGATE(5,6,$F$18:$F$25)),0)) | K25: =IF(G25="","",IFERROR((G25-_xludf.AGGREGATE(5,6,$G$18:$G$25))/(_xludf.AGGREGATE(4,6,$G$18:$G$25)-_xludf.AGGREGATE(5,6,$G$18:$G$25)),0)) | L25: =IF(A25="","",H25*$B$11+I25*$D$11+J25*$F$11+K25*$H$11) | M25: =IF(D25="",NA(),H25) -> #N/A | N25: =IF(D25="",NA(),I25) -> #N/A | O25: =IF(D25="",NA(),J25) -> #N/A | P25: =IF(D25="",NA(),K25) -> #N/A | Q25: =IF(D25="",NA(),L25) -> #N/A | R25: =IFERROR(IF(D25=_xludf.AGGREGATE(5,6,$D$18:$D$25),"Vel ✓ ","")&IF(E25=_xludf.AGGREGATE(5,6,$E$18:$E$25),"SD ✓ ","")&IF(F25=_xludf.AGGREGATE(5,6,$F$18:$F$25),"MR ✓ ","")&IF(G25=_xludf.AGGREGATE(5,6,$G$18:$G$25),"Vert ✓ ",""),"") | T25: =NA() -> #N/A | U25: =NA() -> #N/A
A27: COMPARISON CHARTS
A100: Mode: | B100: test

Sheet Seating Depth Log
A1: Seating Depth Test — Best Jump Finder
A2: SUGGESTED JUMP → | D2: 0.035 | F2: Vel: | G2: 2780.6 | I2: SD: | J2: 0.8 | K2: MR: | L2: 0.16 | M2: Vert: | N2: 0.1 | O2: Best in: All metrics ✓
A3: ↓ Click here to jump to the Charts sheet (Suggested Best Load) ↓
A4: RIFLE & SHOOTER
A5: Rifle: | B5: Tikka T3X CTR 6.5 CM | F5: Shooter: | G5: Demo Shooter | K5: Cartridge: | L5: 6.5 Creedmoor
A6: Barrel: | B6: 24" 1:8 twist, threaded muzzle | F6: Optic: | G6: Leupold Mark 5HD 5-25x56 | K6: Chrono: | L6: Garmin Xero C1 Pro
F7: Turret: | G7: 0.1 Mil
A8: LOAD COMPONENTS (constants for this seating-depth test)
A9: Bullet: | B9: Hornady 140gr ELD-M | F9: Powder: | G9: =IFERROR(LOOKUP(2,1/(GarminSessions!$C$2:$C$200<>""),GarminSessions!$C$2:$C$200),"") -> H4350 | K9: Primer: | L9: CCI BR-2 | N9: Brass: | O9: Hornady
A10: Charge: | B10: 42.4 | F10: OAL: | G10: 2.875 | K10: Dist: | L10: 100
A12: TEST SESSION (date / conditions)
A13: Date: | B13: 46138 | F13: Temp: | G13: 68 | K13: Notes: | L13: Sunny, light breeze. 1500 ft DA.
A15: Test # | B15: Jump (in) | C15: CBTO | D15: Shot 1 | E15: Shot 2 | F15: Shot 3 | G15: Shot 4 | H15: Shot 5 | I15: Avg Vel | J15: ES | K15: SD | L15: Group (in) | M15: Vertical (in) | N15: Vertical SD (in) | O15: Mean Radius (in) | P15: Notes
A16: 1 | B16: =IFERROR(LOOKUP(2,1/(GarminSessions!$A$2:$A$200="S1"),GarminSessions!$B$2:$B$200),NA()) -> 0.005 | C16: =IFERROR($G$10-B16,"") -> 2.87 | D16: =IF(OR('Garmin Xero Import'!E17="",'Garmin Xero Import'!E17=0),"",'Garmin Xero Import'!E17) -> 2782 | E16: =IF(OR('Garmin Xero Import'!F17="",'Garmin Xero Import'!F17=0),"",'Garmin Xero Import'!F17) -> 2778 | F16: =IF(OR('Garmin Xero Import'!G17="",'Garmin Xero Import'!G17=0),"",'Garmin Xero Import'!G17) -> 2780 | G16: =IF(OR('Garmin Xero Import'!H17="",'Garmin Xero Import'!H17=0),"",'Garmin Xero Import'!H17) -> 2784 | H16: =IF(OR('Garmin Xero Import'!I17="",'Garmin Xero Import'!I17=0),"",'Garmin Xero Import'!I17) -> 2780 | I16: =IF(OR('Garmin Xero Import'!O17="",'Garmin Xero Import'!O17=0),"",'Garmin Xero Import'!O17) -> 2781 | J16: =IF(OR('Garmin Xero Import'!Q17="",'Garmin Xero Import'!Q17=0),"",'Garmin Xero Import'!Q17) -> 6 | K16: =IF(OR('Garmin Xero Import'!P17="",'Garmin Xero Import'!P17=0),"",'Garmin Xero Import'!P17) -> 2.2 | L16: =IF(OR('BallisticX Import'!D17="",'BallisticX Import'!D17=0),"",'BallisticX Import'!D17) -> 0.55 | M16: =IF(OR('BallisticX Import'!F17="",'BallisticX Import'!F17=0),"",'BallisticX Import'!F17) -> 0.48 | N16: =IF(OR('BallisticX Import'!J17="",'BallisticX Import'!J17=0),"",'BallisticX Import'!J17) -> 0.17 | O16: 0.652
A17: 2 | B17: =IFERROR(LOOKUP(2,1/(GarminSessions!$A$2:$A$200="S2"),GarminSessions!$B$2:$B$200),NA()) -> 0.02 | C17: =IFERROR($G$10-B17,"") -> 2.855 | D17: =IF(OR('Garmin Xero Import'!E18="",'Garmin Xero Import'!E18=0),"",'Garmin Xero Import'!E18) -> 2780 | E17: =IF(OR('Garmin Xero Import'!F18="",'Garmin Xero Import'!F18=0),"",'Garmin Xero Import'!F18) -> 2778 | F17: =IF(OR('Garmin Xero Import'!G18="",'Garmin Xero Import'!G18=0),"",'Garmin Xero Import'!G18) -> 2782 | G17: =IF(OR('Garmin Xero Import'!H18="",'Garmin Xero Import'!H18=0),"",'Garmin Xero Import'!H18) -> 2776 | H17: =IF(OR('Garmin Xero Import'!I18="",'Garmin Xero Import'!I18=0),"",'Garmin Xero Import'!I18) -> 2780 | I17: =IF(OR('Garmin Xero Import'!O18="",'Garmin Xero Import'!O18=0),"",'Garmin Xero Import'!O18) -> 2780 | J17: =IF(OR('Garmin Xero Import'!Q18="",'Garmin Xero Import'!Q18=0),"",'Garmin Xero Import'!Q18) -> 8 | K17: =IF(OR('Garmin Xero Import'!P18="",'Garmin Xero Import'!P18=0),"",'Garmin Xero Import'!P18) -> 2.4 | L17: =IF(OR('BallisticX Import'!D18="",'BallisticX Import'!D18=0),"",'BallisticX Import'!D18) -> 0.41 | M17: =IF(OR('BallisticX Import'!F18="",'BallisticX Import'!F18=0),"",'BallisticX Import'!F18) -> 0.36 | N17: =IF(OR('BallisticX Import'!J18="",'BallisticX Import'!J18=0),"",'BallisticX Import'!J18) -> 0.13 | O17: 0.338 | P17: 🥈 2nd
A18: 3 | B18: =IFERROR(LOOKUP(2,1/(GarminSessions!$A$2:$A$200="S3"),GarminSessions!$B$2:$B$200),NA()) -> 0.035 | C18: =IFERROR($G$10-B18,"") -> 2.84 | D18: =IF(OR('Garmin Xero Import'!E19="",'Garmin Xero Import'!E19=0),"",'Garmin Xero Import'!E19) -> 2780 | E18: =IF(OR('Garmin Xero Import'!F19="",'Garmin Xero Import'!F19=0),"",'Garmin Xero Import'!F19) -> 2781 | F18: =IF(OR('Garmin Xero Import'!G19="",'Garmin Xero Import'!G19=0),"",'Garmin Xero Import'!G19) -> 2780 | G18: =IF(OR('Garmin Xero Import'!H19="",'Garmin Xero Import'!H19=0),"",'Garmin Xero Import'!H19) -> 2782 | H18: =IF(OR('Garmin Xero Import'!I19="",'Garmin Xero Import'!I19=0),"",'Garmin Xero Import'!I19) -> 2780 | I18: =IF(OR('Garmin Xero Import'!O19="",'Garmin Xero Import'!O19=0),"",'Garmin Xero Import'!O19) -> 2780.6 | J18: =IF(OR('Garmin Xero Import'!Q19="",'Garmin Xero Import'!Q19=0),"",'Garmin Xero Import'!Q19) -> 2 | K18: =IF(OR('Garmin Xero Import'!P19="",'Garmin Xero Import'!P19=0),"",'Garmin Xero Import'!P19) -> 0.8 | L18: =IF(OR('BallisticX Import'!D19="",'BallisticX Import'!D19=0),"",'BallisticX Import'!D19) -> 0.32 | M18: =IF(OR('BallisticX Import'!F19="",'BallisticX Import'!F19=0),"",'BallisticX Import'!F19) -> 0.27 | N18: =IF(OR('BallisticX Import'!J19="",'BallisticX Import'!J19=0),"",'BallisticX Import'!J19) -> 0.1 | O18: 0.001 | P18: 🥇 WINNER
A19: 4 | B19: =IFERROR(LOOKUP(2,1/(GarminSessions!$A$2:$A$200="S4"),GarminSessions!$B$2:$B$200),NA()) -> 0.05 | C19: =IFERROR($G$10-B19,"") -> 2.825 | D19: =IF(OR('Garmin Xero Import'!E20="",'Garmin Xero Import'!E20=0),"",'Garmin Xero Import'!E20) -> 2780 | E19: =IF(OR('Garmin Xero Import'!F20="",'Garmin Xero Import'!F20=0),"",'Garmin Xero Import'!F20) -> 2784 | F19: =IF(OR('Garmin Xero Import'!G20="",'Garmin Xero Import'!G20=0),"",'Garmin Xero Import'!G20) -> 2776 | G19: =IF(OR('Garmin Xero Import'!H20="",'Garmin Xero Import'!H20=0),"",'Garmin Xero Import'!H20) -> 2782 | H19: =IF(OR('Garmin Xero Import'!I20="",'Garmin Xero Import'!I20=0),"",'Garmin Xero Import'!I20) -> 2780 | I19: =IF(OR('Garmin Xero Import'!O20="",'Garmin Xero Import'!O20=0),"",'Garmin Xero Import'!O20) -> 2780 | J19: =IF(OR('Garmin Xero Import'!Q20="",'Garmin Xero Import'!Q20=0),"",'Garmin Xero Import'!Q20) -> 10 | K19: =IF(OR('Garmin Xero Import'!P20="",'Garmin Xero Import'!P20=0),"",'Garmin Xero Import'!P20) -> 3.4 | L19: =IF(OR('BallisticX Import'!D20="",'BallisticX Import'!D20=0),"",'BallisticX Import'!D20) -> 0.48 | M19: =IF(OR('BallisticX Import'!F20="",'BallisticX Import'!F20=0),"",'BallisticX Import'!F20) -> 0.42 | N19: =IF(OR('BallisticX Import'!J20="",'BallisticX Import'!J20=0),"",'BallisticX Import'!J20) -> 0.15 | O19: 0.559 | P19: 🥉 3rd
A20: 5 | B20: =IFERROR(LOOKUP(2,1/(GarminSessions!$A$2:$A$200="S5"),GarminSessions!$B$2:$B$200),NA()) -> 0.065 | C20: =IFERROR($G$10-B20,"") -> 2.81 | D20: =IF(OR('Garmin Xero Import'!E21="",'Garmin Xero Import'!E21=0),"",'Garmin Xero Import'!E21) -> 2780 | E20: =IF(OR('Garmin Xero Import'!F21="",'Garmin Xero Import'!F21=0),"",'Garmin Xero Import'!F21) -> 2786 | F20: =IF(OR('Garmin Xero Import'!G21="",'Garmin Xero Import'!G21=0),"",'Garmin Xero Import'!G21) -> 2774 | G20: =IF(OR('Garmin Xero Import'!H21="",'Garmin Xero Import'!H21=0),"",'Garmin Xero Import'!H21) -> 2784 | H20: =IF(OR('Garmin Xero Import'!I21="",'Garmin Xero Import'!I21=0),"",'Garmin Xero Import'!I21) -> 2776 | I20: =IF(OR('Garmin Xero Import'!O21="",'Garmin Xero Import'!O21=0),"",'Garmin Xero Import'!O21) -> 2780 | J20: =IF(OR('Garmin Xero Import'!Q21="",'Garmin Xero Import'!Q21=0),"",'Garmin Xero Import'!Q21) -> 14 | K20: =IF(OR('Garmin Xero Import'!P21="",'Garmin Xero Import'!P21=0),"",'Garmin Xero Import'!P21) -> 5.1 | L20: =IF(OR('BallisticX Import'!D21="",'BallisticX Import'!D21=0),"",'BallisticX Import'!D21) -> 0.62 | M20: =IF(OR('BallisticX Import'!F21="",'BallisticX Import'!F21=0),"",'BallisticX Import'!F21) -> 0.55 | N20: =IF(OR('BallisticX Import'!J21="",'BallisticX Import'!J21=0),"",'BallisticX Import'!J21) -> 0.19 | O20: 1
A21: 6 | B21: =IFERROR(LOOKUP(2,1/(GarminSessions!$A$2:$A$200="S6"),GarminSessions!$B$2:$B$200),NA()) -> #N/A | C21: =IFERROR($G$10-B21,"") | D21: =IF(OR('Garmin Xero Import'!E22="",'Garmin Xero Import'!E22=0),"",'Garmin Xero Import'!E22) | E21: =IF(OR('Garmin Xero Import'!F22="",'Garmin Xero Import'!F22=0),"",'Garmin Xero Import'!F22) | F21: =IF(OR('Garmin Xero Import'!G22="",'Garmin Xero Import'!G22=0),"",'Garmin Xero Import'!G22) | G21: =IF(OR('Garmin Xero Import'!H22="",'Garmin Xero Import'!H22=0),"",'Garmin Xero Import'!H22) | H21: =IF(OR('Garmin Xero Import'!I22="",'Garmin Xero Import'!I22=0),"",'Garmin Xero Import'!I22) | I21: =IF(OR('Garmin Xero Import'!O22="",'Garmin Xero Import'!O22=0),"",'Garmin Xero Import'!O22) | J21: =IF(OR('Garmin Xero Import'!Q22="",'Garmin Xero Import'!Q22=0),"",'Garmin Xero Import'!Q22) | K21: =IF(OR('Garmin Xero Import'!P22="",'Garmin Xero Import'!P22=0),"",'Garmin Xero Import'!P22) | L21: =IF(OR('BallisticX Import'!D22="",'BallisticX Import'!D22=0),"",'BallisticX Import'!D22) | M21: =IF(OR('BallisticX Import'!F22="",'BallisticX Import'!F22=0),"",'BallisticX Import'!F22) | N21: =IF(OR('BallisticX Import'!J22="",'BallisticX Import'!J22=0),"",'BallisticX Import'!J22) | O21: =NA() -> #N/A
A22: 7 | B22: =IFERROR(LOOKUP(2,1/(GarminSessions!$A$2:$A$200="S7"),GarminSessions!$B$2:$B$200),NA()) -> #N/A | C22: =IFERROR($G$10-B22,"") | D22: =IF(OR('Garmin Xero Import'!E23="",'Garmin Xero Import'!E23=0),"",'Garmin Xero Import'!E23) | E22: =IF(OR('Garmin Xero Import'!F23="",'Garmin Xero Import'!F23=0),"",'Garmin Xero Import'!F23) | F22: =IF(OR('Garmin Xero Import'!G23="",'Garmin Xero Import'!G23=0),"",'Garmin Xero Import'!G23) | G22: =IF(OR('Garmin Xero Import'!H23="",'Garmin Xero Import'!H23=0),"",'Garmin Xero Import'!H23) | H22: =IF(OR('Garmin Xero Import'!I23="",'Garmin Xero Import'!I23=0),"",'Garmin Xero Import'!I23) | I22: =IF(OR('Garmin Xero Import'!O23="",'Garmin Xero Import'!O23=0),"",'Garmin Xero Import'!O23) | J22: =IF(OR('Garmin Xero Import'!Q23="",'Garmin Xero Import'!Q23=0),"",'Garmin Xero Import'!Q23) | K22: =IF(OR('Garmin Xero Import'!P23="",'Garmin Xero Import'!P23=0),"",'Garmin Xero Import'!P23) | L22: =IF(OR('BallisticX Import'!D23="",'BallisticX Import'!D23=0),"",'BallisticX Import'!D23) | M22: =IF(OR('BallisticX Import'!F23="",'BallisticX Import'!F23=0),"",'BallisticX Import'!F23) | N22: =IF(OR('BallisticX Import'!J23="",'BallisticX Import'!J23=0),"",'BallisticX Import'!J23) | O22: =NA() -> #N/A
A23: 8 | B23: =IFERROR(LOOKUP(2,1/(GarminSessions!$A$2:$A$200="S8"),GarminSessions!$B$2:$B$200),NA()) -> #N/A | C23: =IFERROR($G$10-B23,"") | D23: =IF(OR('Garmin Xero Import'!E24="",'Garmin Xero Import'!E24=0),"",'Garmin Xero Import'!E24) | E23: =IF(OR('Garmin Xero Import'!F24="",'Garmin Xero Import'!F24=0),"",'Garmin Xero Import'!F24) | F23: =IF(OR('Garmin Xero Import'!G24="",'Garmin Xero Import'!G24=0),"",'Garmin Xero Import'!G24) | G23: =IF(OR('Garmin Xero Import'!H24="",'Garmin Xero Import'!H24=0),"",'Garmin Xero Import'!H24) | H23: =IF(OR('Garmin Xero Import'!I24="",'Garmin Xero Import'!I24=0),"",'Garmin Xero Import'!I24) | I23: =IF(OR('Garmin Xero Import'!O24="",'Garmin Xero Import'!O24=0),"",'Garmin Xero Import'!O24) | J23: =IF(OR('Garmin Xero Import'!Q24="",'Garmin Xero Import'!Q24=0),"",'Garmin Xero Import'!Q24) | K23: =IF(OR('Garmin Xero Import'!P24="",'Garmin Xero Import'!P24=0),"",'Garmin Xero Import'!P24) | L23: =IF(OR('BallisticX Import'!D24="",'BallisticX Import'!D24=0),"",'BallisticX Import'!D24) | M23: =IF(OR('BallisticX Import'!F24="",'BallisticX Import'!F24=0),"",'BallisticX Import'!F24) | N23: =IF(OR('BallisticX Import'!J24="",'BallisticX Import'!J24=0),"",'BallisticX Import'!J24) | O23: =NA() -> #N/A
A24: 9 | B24: =IFERROR(LOOKUP(2,1/(GarminSessions!$A$2:$A$200="S9"),GarminSessions!$B$2:$B$200),NA()) -> #N/A | C24: =IFERROR($G$10-B24,"") | D24: =IF(OR('Garmin Xero Import'!E25="",'Garmin Xero Import'!E25=0),"",'Garmin Xero Import'!E25) | E24: =IF(OR('Garmin Xero Import'!F25="",'Garmin Xero Import'!F25=0),"",'Garmin Xero Import'!F25) | F24: =IF(OR('Garmin Xero Import'!G25="",'Garmin Xero Import'!G25=0),"",'Garmin Xero Import'!G25) | G24: =IF(OR('Garmin Xero Import'!H25="",'Garmin Xero Import'!H25=0),"",'Garmin Xero Import'!H25) | H24: =IF(OR('Garmin Xero Import'!I25="",'Garmin Xero Import'!I25=0),"",'Garmin Xero Import'!I25) | I24: =IF(OR('Garmin Xero Import'!O25="",'Garmin Xero Import'!O25=0),"",'Garmin Xero Import'!O25) | J24: =IF(OR('Garmin Xero Import'!Q25="",'Garmin Xero Import'!Q25=0),"",'Garmin Xero Import'!Q25) | K24: =IF(OR('Garmin Xero Import'!P25="",'Garmin Xero Import'!P25=0),"",'Garmin Xero Import'!P25) | L24: =IF(OR('BallisticX Import'!D25="",'BallisticX Import'!D25=0),"",'BallisticX Import'!D25) | M24: =IF(OR('BallisticX Import'!F25="",'BallisticX Import'!F25=0),"",'BallisticX Import'!F25) | N24: =IF(OR('BallisticX Import'!J25="",'BallisticX Import'!J25=0),"",'BallisticX Import'!J25) | O24: =NA() -> #N/A
A25: 10 | B25: =IFERROR(LOOKUP(2,1/(GarminSessions!$A$2:$A$200="S10"),GarminSessions!$B$2:$B$200),NA()) -> #N/A | C25: =IFERROR($G$10-B25,"") | D25: =IF(OR('Garmin Xero Import'!E26="",'Garmin Xero Import'!E26=0),"",'Garmin Xero Import'!E26) | E25: =IF(OR('Garmin Xero Import'!F26="",'Garmin Xero Import'!F26=0),"",'Garmin Xero Import'!F26) | F25: =IF(OR('Garmin Xero Import'!G26="",'Garmin Xero Import'!G26=0),"",'Garmin Xero Import'!G26) | G25: =IF(OR('Garmin Xero Import'!H26="",'Garmin Xero Import'!H26=0),"",'Garmin Xero Import'!H26) | H25: =IF(OR('Garmin Xero Import'!I26="",'Garmin Xero Import'!I26=0),"",'Garmin Xero Import'!I26) | I25: =IF(OR('Garmin Xero Import'!O26="",'Garmin Xero Import'!O26=0),"",'Garmin Xero Import'!O26) | J25: =IF(OR('Garmin Xero Import'!Q26="",'Garmin Xero Import'!Q26=0),"",'Garmin Xero Import'!Q26) | K25: =IF(OR('Garmin Xero Import'!P26="",'Garmin Xero Import'!P26=0),"",'Garmin Xero Import'!P26) | L25: =IF(OR('BallisticX Import'!D26="",'BallisticX Import'!D26=0),"",'BallisticX Import'!D26) | M25: =IF(OR('BallisticX Import'!F26="",'BallisticX Import'!F26=0),"",'BallisticX Import'!F26) | N25: =IF(OR('BallisticX Import'!J26="",'BallisticX Import'!J26=0),"",'BallisticX Import'!J26) | O25: =NA() -> #N/A
A26: → Save Suggested Load to Library ←
A27: ANALYSIS — Suggested Best Jump (Composite Score)
A28: Reset weights | B28: Velocity | C28: 0.15 | E28: SD | F28: 0.25 | H28: MR | I28: 0.25 | K28: Vertical SD | L28: 0.35 | N28: Sum: | O28: =SUM(C28,F28,I28,L28) -> 1
A29: Jump | D29: Avg Vel (fps) | E29: SD (fps) | F29: Mean Radius (MOA) | G29: Vertical SD (MOA) | H29: Norm Vel | I29: Norm SD | J29: Norm MR | K29: Norm Vertical SD | L29: Composite Score | M29: Rank | N29: Best in
A30: 0.005 | D30: 2781 | E30: 2.2 | F30: 0.27 | G30: 0.17 | H30: 0.767 | I30: 0.326 | J30: 0.733 | K30: 0.778 | L30: 0.652 | M30: 4
A31: 0.02 | D31: 2780 | E31: 2.4 | F31: 0.21 | G31: 0.13 | H31: 0.3 | I31: 0.372 | J31: 0.333 | K31: 0.333 | L31: 0.338 | M31: 2
A32: 0.035 | D32: 2780.6 | E32: 0.8 | F32: 0.16 | G32: 0.1 | H32: 0.001 | I32: 0.001 | J32: 0.001 | K32: 0.001 | L32: 0.001 | M32: 1 | N32: All metrics ✓
A33: 0.05 | D33: 2780 | E33: 3.4 | F33: 0.24 | G33: 0.15 | H33: 0.533 | I33: 0.605 | J33: 0.533 | K33: 0.556 | L33: 0.559 | M33: 3
A34: 0.065 | D34: 2780 | E34: 5.1 | F34: 0.31 | G34: 0.19 | H34: 1 | I34: 1 | J34: 1 | K34: 1 | L34: 1 | M34: 5
A35: =NA() -> #N/A | B35: =IFERROR(IF($B$100="window",B21,""),"") | C35: =IFERROR(IF($B$100="window",B23,""),"") | D35: =NA() -> #N/A | E35: =NA() -> #N/A | F35: =NA() -> #N/A | G35: =NA() -> #N/A | H35: =NA() -> #N/A | I35: =NA() -> #N/A | J35: =NA() -> #N/A | K35: =NA() -> #N/A | ... N35: =NA() -> #N/A
A36: =NA() -> #N/A | B36: =IFERROR(IF($B$100="window",B22,""),"") | C36: =IFERROR(IF($B$100="window",B24,""),"") | D36: =NA() -> #N/A | E36: =NA() -> #N/A | F36: =NA() -> #N/A | G36: =NA() -> #N/A | H36: =NA() -> #N/A | I36: =NA() -> #N/A | J36: =NA() -> #N/A | K36: =NA() -> #N/A | ... N36: =NA() -> #N/A
A37: =NA() -> #N/A | B37: =IFERROR(IF($B$100="window",B23,""),"") | C37: =IFERROR(IF($B$100="window",B25,""),"") | D37: =NA() -> #N/A | E37: =NA() -> #N/A | F37: =NA() -> #N/A | G37: =NA() -> #N/A | H37: =NA() -> #N/A | I37: =NA() -> #N/A | J37: =NA() -> #N/A | K37: =NA() -> #N/A | ... N37: =NA() -> #N/A
A100: Mode: | B100: =IF(COUNT(B16:B25)>=5,"window","test") -> window

Sheet Garmin Xero Import
A1: Garmin Xero Import — ShotView CSV sessions
A2: This sheet feeds the Load Log and Seating Depth tabs. The shot cells over there are wired to pull from these specific rows. Just paste each Garmin session's shot velocities into the matching row's Shot 1–10 cells (E:N). Avg / SD / ES auto-compute.
A3: POWDER LADDER (Load Log P1–P10 → rows 6–15)
A5: Tag | B5: Date | C5: Session Title | D5: # Shots | E5: Shot 1 (fps) | F5: Shot 2 (fps) | G5: Shot 3 (fps) | H5: Shot 4 (fps) | I5: Shot 5 (fps) | J5: Shot 6 (fps) | K5: Shot 7 (fps) | L5: Shot 8 (fps) | M5: Shot 9 (fps) | N5: Shot 10 (fps) | O5: Avg Vel (fps) | P5: SD (fps) | Q5: ES (fps) | R5: Bullet Wt (gr) | S5: Avg KE (ft·lb) | T5: Notes
A6: P1 | B6: =IFERROR(LOOKUP(2,1/(GarminSessions!$A$2:$A$200=$A6),GarminSessions!$D$2:$D$200),"") -> 2026-04-12 | C6: =IFERROR(IF(LOOKUP(2,1/(GarminSessions!$A$2:$A$200=$A6),GarminSessions!$T$2:$T$200)="","",LOOKUP(2,1/(GarminSessions!$A$2:$A$200=$A6),GarminSessions!$T$2:$T$200)),"") -> 6.5 CM H4350 41.5gr | D6: =COUNT(E6:N6) -> 10 | E6: =IFERROR(IF(LOOKUP(2,1/(GarminSessions!$A$2:$A$200=$A6),GarminSessions!$E$2:$E$200)>0,LOOKUP(2,1/(GarminSessions!$A$2:$A$200=$A6),GarminSessions!$E$2:$E$200),""),"") -> 2710 | F6: =IFERROR(IF(LOOKUP(2,1/(GarminSessions!$A$2:$A$200=$A6),GarminSessions!$F$2:$F$200)>0,LOOKUP(2,1/(GarminSessions!$A$2:$A$200=$A6),GarminSessions!$F$2:$F$200),""),"") -> 2718 | G6: =IFERROR(IF(LOOKUP(2,1/(GarminSessions!$A$2:$A$200=$A6),GarminSessions!$G$2:$G$200)>0,LOOKUP(2,1/(GarminSessions!$A$2:$A$200=$A6),GarminSessions!$G$2:$G$200),""),"") -> 2705 | H6: =IFERROR(IF(LOOKUP(2,1/(GarminSessions!$A$2:$A$200=$A6),GarminSessions!$H$2:$H$200)>0,LOOKUP(2,1/(GarminSessions!$A$2:$A$200=$A6),GarminSessions!$H$2:$H$200),""),"") -> 2720 | I6: =IFERROR(IF(LOOKUP(2,1/(GarminSessions!$A$2:$A$200=$A6),GarminSessions!$I$2:$I$200)>0,LOOKUP(2,1/(GarminSessions!$A$2:$A$200=$A6),GarminSessions!$I$2:$I$200),""),"") -> 2715 | J6: =IFERROR(IF(LOOKUP(2,1/(GarminSessions!$A$2:$A$200=$A6),GarminSessions!$J$2:$J$200)>0,LOOKUP(2,1/(GarminSessions!$A$2:$A$200=$A6),GarminSessions!$J$2:$J$200),""),"") -> 2712 | K6: =IFERROR(IF(LOOKUP(2,1/(GarminSessions!$A$2:$A$200=$A6),GarminSessions!$K$2:$K$200)>0,LOOKUP(2,1/(GarminSessions!$A$2:$A$200=$A6),GarminSessions!$K$2:$K$200),""),"") -> 2722 | L6: =IFERROR(IF(LOOKUP(2,1/(GarminSessions!$A$2:$A$200=$A6),GarminSessions!$L$2:$L$200)>0,LOOKUP(2,1/(GarminSessions!$A$2:$A$200=$A6),GarminSessions!$L$2:$L$200),""),"") -> 2708 | M6: =IFERROR(IF(LOOKUP(2,1/(GarminSessions!$A$2:$A$200=$A6),GarminSessions!$M$2:$M$200)>0,LOOKUP(2,1/(GarminSessions!$A$2:$A$200=$A6),GarminSessions!$M$2:$M$200),""),"") -> 2716 | N6: =IFERROR(IF(LOOKUP(2,1/(GarminSessions!$A$2:$A$200=$A6),GarminSessions!$N$2:$N$200)>0,LOOKUP(2,1/(GarminSessions!$A$2:$A$200=$A6),GarminSessions!$N$2:$N$200),""),"") -> 2724 | O6: =IFERROR(LOOKUP(2,1/(GarminSessions!$A$2:$A$200=$A6),GarminSessions!$O$2:$O$200),"") -> 2715 | P6: =IFERROR(LOOKUP(2,1/(GarminSessions!$A$2:$A$200=$A6),GarminSessions!$P$2:$P$200),"") -> 6.7 | Q6: =IFERROR(LOOKUP(2,1/(GarminSessions!$A$2:$A$200=$A6),GarminSessions!$Q$2:$Q$200),"") -> 19 | R6: =IFERROR(LOOKUP(2,1/(GarminSessions!$A$2:$A$200=$A6),GarminSessions!$R$2:$R$200),"") -> 140 | S6: =IFERROR(LOOKUP(2,1/(GarminSessions!$A$2:$A$200=$A6),GarminSessions!$S$2:$S$200),"") -> 2293 | T6: =IFERROR(IF(LOOKUP(2,1/(GarminSessions!$A$2:$A$200=$A6),GarminSessions!$U$2:$U$200)="","",LOOKUP(2,1/(GarminSessions!$A$2:$A$200=$A6),GarminSessions!$U$2:$U$200)),"") -> Hornady brass, CCI BR-2 primer, 2.875 OAL
A7: P2 | B7: =IFERROR(LOOKUP(2,1/(GarminSessions!$A$2:$A$200=$A7),GarminSessions!$D$2:$D$200),"") -> 2026-04-12 | C7: =IFERROR(IF(LOOKUP(2,1/(GarminSessions!$A$2:$A$200=$A7),GarminSessions!$T$2:$T$200)="","",LOOKUP(2,1/(GarminSessions!$A$2:$A$200=$A7),GarminSessions!$T$2:$T$200)),"") -> 6.5 CM H4350 41.8gr | D7: =COUNT(E7:N7) -> 10 | E7: =IFERROR(IF(LOOKUP(2,1/(GarminSessions!$A$2:$A$200=$A7),GarminSessions!$E$2:$E$200)>0,LOOKUP(2,1/(GarminSessions!$A$2:$A$200=$A7),GarminSessions!$E$2:$E$200),""),"") -> 2732 | F7: =IFERROR(IF(LOOKUP(2,1/(GarminSessions!$A$2:$A$200=$A7),GarminSessions!$F$2:$F$200)>0,LOOKUP(2,1/(GarminSessions!$A$2:$A$200=$A7),GarminSessions!$F$2:$F$200),""),"") -> 2748 | G7: =IFERROR(IF(LOOKUP(2,1/(GarminSessions!$A$2:$A$200=$A7),GarminSessions!$G$2:$G$200)>0,LOOKUP(2,1/(GarminSessions!$A$2:$A$200=$A7),GarminSessions!$G$2:$G$200),""),"") -> 2725 | H7: =IFERROR(IF(LOOKUP(2,1/(GarminSessions!$A$2:$A$200=$A7),GarminSessions!$H$2:$H$200)>0,LOOKUP(2,1/(GarminSessions!$A$2:$A$200=$A7),GarminSessions!$H$2:$H$200),""),"") -> 2740 | I7: =IFERROR(IF(LOOKUP(2,1/(GarminSessions!$A$2:$A$200=$A7),GarminSessions!$I$2:$I$200)>0,LOOKUP(2,1/(GarminSessions!$A$2:$A$200=$A7),GarminSessions!$I$2:$I$200),""),"") -> 2738 | J7: =IFERROR(IF(LOOKUP(2,1/(GarminSessions!$A$2:$A$200=$A7),GarminSessions!$J$2:$J$200)>0,LOOKUP(2,1/(GarminSessions!$A$2:$A$200=$A7),GarminSessions!$J$2:$J$200),""),"") -> 2734 | K7: =IFERROR(IF(LOOKUP(2,1/(GarminSessions!$A$2:$A$200=$A7),GarminSessions!$K$2:$K$200)>0,LOOKUP(2,1/(GarminSessions!$A$2:$A$200=$A7),GarminSessions!$K$2:$K$200),""),"") -> 2742 | L7: =IFERROR(IF(LOOKUP(2,1/(GarminSessions!$A$2:$A$200=$A7),GarminSessions!$L$2:$L$200)>0,LOOKUP(2,1/(GarminSessions!$A$2:$A$200=$A7),GarminSessions!$L$2:$L$200),""),"") -> 2728 | M7: =IFERROR(IF(LOOKUP(2,1/(GarminSessions!$A$2:$A$200=$A7),GarminSessions!$M$2:$M$200)>0,LOOKUP(2,1/(GarminSessions!$A$2:$A$200=$A7),GarminSessions!$M$2:$M$200),""),"") -> 2736 | N7: =IFERROR(IF(LOOKUP(2,1/(GarminSessions!$A$2:$A$200=$A7),GarminSessions!$N$2:$N$200)>0,LOOKUP(2,1/(GarminSessions!$A$2:$A$200=$A7),GarminSessions!$N$2:$N$200),""),"") -> 2747 | O7: =IFERROR(LOOKUP(2,1/(GarminSessions!$A$2:$A$200=$A7),GarminSessions!$O$2:$O$200),"") -> 2737 | P7: =IFERROR(LOOKUP(2,1/(GarminSessions!$A$2:$A$200=$A7),GarminSessions!$P$2:$P$200),"") -> 7.8 | Q7: =IFERROR(LOOKUP(2,1/(GarminSessions!$A$2:$A$200=$A7),GarminSessions!$Q$2:$Q$200),"") -> 23 | R7: =IFERROR(LOOKUP(2,1/(GarminSessions!$A$2:$A$200=$A7),GarminSessions!$R$2:$R$200),"") -> 140 | S7: =IFERROR(LOOKUP(2,1/(GarminSessions!$A$2:$A$200=$A7),GarminSessions!$S$2:$S$200),"") -> 2330 | T7: =IFERROR(IF(LOOKUP(2,1/(GarminSessions!$A$2:$A$200=$A7),GarminSessions!$U$2:$U$200)="","",LOOKUP(2,1/(GarminSessions!$A$2:$A$200=$A7),GarminSessions!$U$2:$U$200)),"") -> Hornady brass, CCI BR-2 primer, 2.875 OAL
A8: P3 | B8: =IFERROR(LOOKUP(2,1/(GarminSessions!$A$2:$A$200=$A8),GarminSessions!$D$2:$D$200),"") -> 2026-04-12 | C8: =IFERROR(IF(LOOKUP(2,1/(GarminSessions!$A$2:$A$200=$A8),GarminSessions!$T$2:$T$200)="","",LOOKUP(2,1/(GarminSessions!$A$2:$A$200=$A8),GarminSessions!$T$2:$T$200)),"") -> 6.5 CM H4350 42.1gr | D8: =COUNT(E8:N8) -> 10 | E8: =IFERROR(IF(LOOKUP(2,1/(GarminSessions!$A$2:$A$200=$A8),GarminSessions!$E$2:$E$200)>0,LOOKUP(2,1/(GarminSessions!$A$2:$A$200=$A8),GarminSessions!$E$2:$E$200),""),"") -> 2755 | F8: =IFERROR(IF(LOOKUP(2,1/(GarminSessions!$A$2:$A$200=$A8),GarminSessions!$F$2:$F$200)>0,LOOKUP(2,1/(GarminSessions!$A$2:$A$200=$A8),GarminSessions!$F$2:$F$200),""),"") -> 2762 | G8: =IFERROR(IF(LOOKUP(2,1/(GarminSessions!$A$2:$A$200=$A8),GarminSessions!$G$2:$G$200)>0,LOOKUP(2,1/(GarminSessions!$A$2:$A$200=$A8),GarminSessions!$G$2:$G$200),""),"") -> 2750 | H8: =IFERROR(IF(LOOKUP(2,1/(GarminSessions!$A$2:$A$200=$A8),GarminSessions!$H$2:$H$200)>0,LOOKUP(2,1/(GarminSessions!$A$2:$A$200=$A8),GarminSessions!$H$2:$H$200),""),"") -> 2768 | I8: =IFERROR(IF(LOOKUP(2,1/(GarminSessions!$A$2:$A$200=$A8),GarminSessions!$I$2:$I$200)>0,LOOKUP(2,1/(GarminSessions!$A$2:$A$200=$A8),GarminSessions!$I$2:$I$200),""),"") -> 2760 | J8: =IFERROR(IF(LOOKUP(2,1/(GarminSessions!$A$2:$A$200=$A8),GarminSessions!$J$2:$J$200)>0,LOOKUP(2,1/(GarminSessions!$A$2:$A$200=$A8),GarminSessions!$J$2:$J$200),""),"") -> 2758 | K8: =IFERROR(IF(LOOKUP(2,1/(GarminSessions!$A$2:$A$200=$A8),GarminSessions!$K$2:$K$200)>0,LOOKUP(2,1/(GarminSessions!$A$2:$A$200=$A8),GarminSessions!$K$2:$K$200),""),"") -> 2765 | L8: =IFERROR(IF(LOOKUP(2,1/(GarminSessions!$A$2:$A$200=$A8),GarminSessions!$L$2:$L$200)>0,LOOKUP(2,1/(GarminSessions!$A$2:$A$200=$A8),GarminSessions!$L$2:$L$200),""),"") -> 2752 | M8: =IFERROR(IF(LOOKUP(2,1/(GarminSessions!$A$2:$A$200=$A8),GarminSessions!$M$2:$M$200)>0,LOOKUP(2,1/(GarminSessions!$A$2:$A$200=$A8),GarminSessions!$M$2:$M$200),""),"") -> 2760 | N8: =IFERROR(IF(LOOKUP(2,1/(GarminSessions!$A$2:$A$200=$A8),GarminSessions!$N$2:$N$200)>0,LOOKUP(2,1/(GarminSessions!$A$2:$A$200=$A8),GarminSessions!$N$2:$N$200),""),"") -> 2770 | O8: =IFERROR(LOOKUP(2,1/(GarminSessions!$A$2:$A$200=$A8),GarminSessions!$O$2:$O$200),"") -> 2760 | P8: =IFERROR(LOOKUP(2,1/(GarminSessions!$A$2:$A$200=$A8),GarminSessions!$P$2:$P$200),"") -> 6.4 | Q8: =IFERROR(LOOKUP(2,1/(GarminSessions!$A$2:$A$200=$A8),GarminSessions!$Q$2:$Q$200),"") -> 20 | R8: =IFERROR(LOOKUP(2,1/(GarminSessions!$A$2:$A$200=$A8),GarminSessions!$R$2:$R$200),"") -> 140 | S8: =IFERROR(LOOKUP(2,1/(GarminSessions!$A$2:$A$200=$A8),GarminSessions!$S$2:$S$200),"") -> 2369 | T8: =IFERROR(IF(LOOKUP(2,1/(GarminSessions!$A$2:$A$200=$A8),GarminSessions!$U$2:$U$200)="","",LOOKUP(2,1/(GarminSessions!$A$2:$A$200=$A8),GarminSessions!$U$2:$U$200)),"") -> Hornady brass, CCI BR-2 primer, 2.875 OAL
A9: P4 | B9: =IFERROR(LOOKUP(2,1/(GarminSessions!$A$2:$A$200=$A9),GarminSessions!$D$2:$D$200),"") -> 2026-04-12 | C9: =IFERROR(IF(LOOKUP(2,1/(GarminSessions!$A$2:$A$200=$A9),GarminSessions!$T$2:$T$200)="","",LOOKUP(2,1/(GarminSessions!$A$2:$A$200=$A9),GarminSessions!$T$2:$T$200)),"") -> 6.5 CM H4350 42.4gr (WINNER) | D9: =COUNT(E9:N9) -> 10 | E9: =IFERROR(IF(LOOKUP(2,1/(GarminSessions!$A$2:$A$200=$A9),GarminSessions!$E$2:$E$200)>0,LOOKUP(2,1/(GarminSessions!$A$2:$A$200=$A9),GarminSessions!$E$2:$E$200),""),"") -> 2778 | F9: =IFERROR(IF(LOOKUP(2,1/(GarminSessions!$A$2:$A$200=$A9),GarminSessions!$F$2:$F$200)>0,LOOKUP(2,1/(GarminSessions!$A$2:$A$200=$A9),GarminSessions!$F$2:$F$200),""),"") -> 2782 | G9: =IFERROR(IF(LOOKUP(2,1/(GarminSessions!$A$2:$A$200=$A9),GarminSessions!$G$2:$G$200)>0,LOOKUP(2,1/(GarminSessions!$A$2:$A$200=$A9),GarminSessions!$G$2:$G$200),""),"") -> 2776 | H9: =IFERROR(IF(LOOKUP(2,1/(GarminSessions!$A$2:$A$200=$A9),GarminSessions!$H$2:$H$200)>0,LOOKUP(2,1/(GarminSessions!$A$2:$A$200=$A9),GarminSessions!$H$2:$H$200),""),"") -> 2784 | I9: =IFERROR(IF(LOOKUP(2,1/(GarminSessions!$A$2:$A$200=$A9),GarminSessions!$I$2:$I$200)>0,LOOKUP(2,1/(GarminSessions!$A$2:$A$200=$A9),GarminSessions!$I$2:$I$200),""),"") -> 2780 | J9: =IFERROR(IF(LOOKUP(2,1/(GarminSessions!$A$2:$A$200=$A9),GarminSessions!$J$2:$J$200)>0,LOOKUP(2,1/(GarminSessions!$A$2:$A$200=$A9),GarminSessions!$J$2:$J$200),""),"") -> 2779 | K9: =IFERROR(IF(LOOKUP(2,1/(GarminSessions!$A$2:$A$200=$A9),GarminSessions!$K$2:$K$200)>0,LOOKUP(2,1/(GarminSessions!$A$2:$A$200=$A9),GarminSessions!$K$2:$K$200),""),"") -> 2782 | L9: =IFERROR(IF(LOOKUP(2,1/(GarminSessions!$A$2:$A$200=$A9),GarminSessions!$L$2:$L$200)>0,LOOKUP(2,1/(GarminSessions!$A$2:$A$200=$A9),GarminSessions!$L$2:$L$200),""),"") -> 2778 | M9: =IFERROR(IF(LOOKUP(2,1/(GarminSessions!$A$2:$A$200=$A9),GarminSessions!$M$2:$M$200)>0,LOOKUP(2,1/(GarminSessions!$A$2:$A$200=$A9),GarminSessions!$M$2:$M$200),""),"") -> 2780 | N9: =IFERROR(IF(LOOKUP(2,1/(GarminSessions!$A$2:$A$200=$A9),GarminSessions!$N$2:$N$200)>0,LOOKUP(2,1/(GarminSessions!$A$2:$A$200=$A9),GarminSessions!$N$2:$N$200),""),"") -> 2781 | O9: =IFERROR(LOOKUP(2,1/(GarminSessions!$A$2:$A$200=$A9),GarminSessions!$O$2:$O$200),"") -> 2780 | P9: =IFERROR(LOOKUP(2,1/(GarminSessions!$A$2:$A$200=$A9),GarminSessions!$P$2:$P$200),"") -> 2.5 | Q9: =IFERROR(LOOKUP(2,1/(GarminSessions!$A$2:$A$200=$A9),GarminSessions!$Q$2:$Q$200),"") -> 8 | R9: =IFERROR(LOOKUP(2,1/(GarminSessions!$A$2:$A$200=$A9),GarminSessions!$R$2:$R$200),"") -> 140 | S9: =IFERROR(LOOKUP(2,1/(GarminSessions!$A$2:$A$200=$A9),GarminSessions!$S$2:$S$200),"") -> 2402 | T9: =IFERROR(IF(LOOKUP(2,1/(GarminSessions!$A$2:$A$200=$A9),GarminSessions!$U$2:$U$200)="","",LOOKUP(2,1/(GarminSessions!$A$2:$A$200=$A9),GarminSessions!$U$2:$U$200)),"") -> Hornady brass, CCI BR-2 primer, 2.875 OAL
